[2023-03-09 05:00:00,011] ERROR: 获取群列表错误
Traceback (most recent call last):
  File "/root/new_qqbot/yobot/src/client/ybplugins/clan_battle/battle.py", line 165, in _update_group_list_async
    group_list = await self.api.get_group_list()
  File "/root/.local/lib/python3.6/site-packages/aiocqhttp/api.py", line 184, in call_action
    raise ApiNotAvailable
aiocqhttp.exceptions.ApiNotAvailable
[2023-03-11 05:00:00,035] ERROR: 获取群列表错误
Traceback (most recent call last):
  File "/root/new_qqbot/yobot/src/client/ybplugins/clan_battle/battle.py", line 165, in _update_group_list_async
    group_list = await self.api.get_group_list()
  File "/root/.local/lib/python3.6/site-packages/aiocqhttp/api.py", line 184, in call_action
    raise ApiNotAvailable
aiocqhttp.exceptions.ApiNotAvailable
[2023-03-12 05:00:00,014] ERROR: 获取群列表错误
Traceback (most recent call last):
  File "/root/new_qqbot/yobot/src/client/ybplugins/clan_battle/battle.py", line 165, in _update_group_list_async
    group_list = await self.api.get_group_list()
  File "/root/.local/lib/python3.6/site-packages/aiocqhttp/api.py", line 184, in call_action
    raise ApiNotAvailable
aiocqhttp.exceptions.ApiNotAvailable
[2023-03-13 05:00:00,034] ERROR: 获取群列表错误
Traceback (most recent call last):
  File "/root/new_qqbot/yobot/src/client/ybplugins/clan_battle/battle.py", line 165, in _update_group_list_async
    group_list = await self.api.get_group_list()
  File "/root/.local/lib/python3.6/site-packages/aiocqhttp/api.py", line 184, in call_action
    raise ApiNotAvailable
aiocqhttp.exceptions.ApiNotAvailable
[2023-03-14 05:00:00,012] ERROR: 获取群列表错误
Traceback (most recent call last):
  File "/root/new_qqbot/yobot/src/client/ybplugins/clan_battle/battle.py", line 165, in _update_group_list_async
    group_list = await self.api.get_group_list()
  File "/root/.local/lib/python3.6/site-packages/aiocqhttp/api.py", line 184, in call_action
    raise ApiNotAvailable
aiocqhttp.exceptions.ApiNotAvailable
[2023-04-15 05:00:00,035] ERROR: 获取群列表错误
Traceback (most recent call last):
  File "/root/new_qqbot/yobot/src/client/ybplugins/clan_battle/battle.py", line 165, in _update_group_list_async
    group_list = await self.api.get_group_list()
  File "/root/.local/lib/python3.6/site-packages/aiocqhttp/api.py", line 184, in call_action
    raise ApiNotAvailable
aiocqhttp.exceptions.ApiNotAvailable
[2023-04-16 05:00:00,035] ERROR: 获取群列表错误
Traceback (most recent call last):
  File "/root/new_qqbot/yobot/src/client/ybplugins/clan_battle/battle.py", line 165, in _update_group_list_async
    group_list = await self.api.get_group_list()
  File "/root/.local/lib/python3.6/site-packages/aiocqhttp/api.py", line 184, in call_action
    raise ApiNotAvailable
aiocqhttp.exceptions.ApiNotAvailable
[2023-04-17 05:00:00,036] ERROR: 获取群列表错误
Traceback (most recent call last):
  File "/root/new_qqbot/yobot/src/client/ybplugins/clan_battle/battle.py", line 165, in _update_group_list_async
    group_list = await self.api.get_group_list()
  File "/root/.local/lib/python3.6/site-packages/aiocqhttp/api.py", line 184, in call_action
    raise ApiNotAvailable
aiocqhttp.exceptions.ApiNotAvailable
[2023-04-18 05:00:00,568] ERROR: 获取群列表错误
Traceback (most recent call last):
  File "/root/new_qqbot/yobot/src/client/ybplugins/clan_battle/battle.py", line 165, in _update_group_list_async
    group_list = await self.api.get_group_list()
  File "/root/.local/lib/python3.6/site-packages/aiocqhttp/api.py", line 184, in call_action
    raise ApiNotAvailable
aiocqhttp.exceptions.ApiNotAvailable
[2023-04-19 05:00:00,025] ERROR: 获取群列表错误
Traceback (most recent call last):
  File "/root/new_qqbot/yobot/src/client/ybplugins/clan_battle/battle.py", line 165, in _update_group_list_async
    group_list = await self.api.get_group_list()
  File "/root/.local/lib/python3.6/site-packages/aiocqhttp/api.py", line 184, in call_action
    raise ApiNotAvailable
aiocqhttp.exceptions.ApiNotAvailable
[2023-04-20 05:00:00,023] ERROR: 获取群列表错误
Traceback (most recent call last):
  File "/root/new_qqbot/yobot/src/client/ybplugins/clan_battle/battle.py", line 165, in _update_group_list_async
    group_list = await self.api.get_group_list()
  File "/root/.local/lib/python3.6/site-packages/aiocqhttp/api.py", line 184, in call_action
    raise ApiNotAvailable
aiocqhttp.exceptions.ApiNotAvailable
[2023-04-21 05:00:00,015] ERROR: 获取群列表错误
Traceback (most recent call last):
  File "/root/new_qqbot/yobot/src/client/ybplugins/clan_battle/battle.py", line 165, in _update_group_list_async
    group_list = await self.api.get_group_list()
  File "/root/.local/lib/python3.6/site-packages/aiocqhttp/api.py", line 184, in call_action
    raise ApiNotAvailable
aiocqhttp.exceptions.ApiNotAvailable
[2023-04-22 05:00:00,025] ERROR: 获取群列表错误
Traceback (most recent call last):
  File "/root/new_qqbot/yobot/src/client/ybplugins/clan_battle/battle.py", line 165, in _update_group_list_async
    group_list = await self.api.get_group_list()
  File "/root/.local/lib/python3.6/site-packages/aiocqhttp/api.py", line 184, in call_action
    raise ApiNotAvailable
aiocqhttp.exceptions.ApiNotAvailable
[2023-04-23 05:00:00,023] ERROR: 获取群列表错误
Traceback (most recent call last):
  File "/root/new_qqbot/yobot/src/client/ybplugins/clan_battle/battle.py", line 165, in _update_group_list_async
    group_list = await self.api.get_group_list()
  File "/root/.local/lib/python3.6/site-packages/aiocqhttp/api.py", line 184, in call_action
    raise ApiNotAvailable
aiocqhttp.exceptions.ApiNotAvailable
